I'm sorry, but an uncaught exception occurred.

While running game code:
  File "game/tl/russian/common.rpy", line 522, in script
    old "sound volume"
Exception: A translation for "sound volume" already exists at game/tl/russian/common.rpy:519.

-- Full Traceback ------------------------------------------------------------

Full traceback:
  File "game/tl/russian/common.rpy", line 522, in script
    old "sound volume"
  File "D:\Programs\RenPy\renpy-6.99.14-sdk\renpy\ast.py", line 2237, in execute
    renpy.translation.add_string_translation(self.language, self.old, self.new, newloc)
  File "D:\Programs\RenPy\renpy-6.99.14-sdk\renpy\translation\__init__.py", line 439, in add_string_translation
    stl.add(old, new, newloc)
  File "D:\Programs\RenPy\renpy-6.99.14-sdk\renpy\translation\__init__.py", line 377, in add
    quote_unicode(old), fn, line))
Exception: A translation for "sound volume" already exists at game/tl/russian/common.rpy:519.

Windows-8-6.2.9200
Ren'Py 7.0.0.196
Lonely Road 1.0
Wed Jul 18 23:37:47 2018
